<?xml version="1.0"?>

<robot name="pandalite">
    <!-- Materials -->
    <material name="grey">
        <color rgba="0.5 0.5 0.5 1.0"/>
    </material>
    <material name="orange">
        <color rgba="1.0 0.5 0.0 1.0"/>
    </material>
    <material name="blue">
        <color rgba="0.2 0.4 0.8 1.0"/>
    </material>

    <!-- Base Link-->
    <link name="base_link">
        <visual>
            <origin xyz="0 0 0.04" rpy="0 0 0"/>
            <geometry>
                <cylinder radius="0.06" length="0.08"/>
            </geometry>
            <material name="grey"/>
        </visual>
        <inertial>
            <origin xyz="0 0 0.04" rpy="0 0 0"/>
            <mass value="1"/>
            <inertia ixx="0.002" ixy="0" ixz="0"
               iyy="0.002" iyz="0"
               izz="0.002"/>
        </inertial>
    </link>

    <!-- Joint 1 (Revolute joint between base_link and link_1) -->
     <joint name="base_link_1_joint" type="revolute">
        <parent link="base_link"/>
        <child link="link_1"/>
        <origin xyz="0 0 0.08" rpy="0 0 0"/>
        <axis xyz="0 0 1"/>
        <limit lower="-3.14" upper="3.14" velocity="2.5" effort="10.0"/>
     </joint>

    <!-- Link 1 (Shorter cylinder above base_link) -->
     <link name="link_1">
        <visual>
            <origin xyz="0 0 0.03" rpy="0 0 0"/>
            <geometry>
              <cylinder radius="0.04" length="0.06"/>
            </geometry>
            <material name="orange"/>
          </visual>
          <inertial>
            <origin xyz="0 0 0.03" rpy="0 0 0"/>
            <mass value="0.5"/>
            <inertia ixx="0.0005" ixy="0" ixz="0"
                     iyy="0.0005" iyz="0"
                     izz="0.0005"/>
          </inertial>
     </link>
</robot>